Traceback (most recent call last):
  File "/home/andrew/anaconda3/envs/jupbooks/lib/python3.8/site-packages/jupyter_cache/executors/utils.py", line 51, in single_nb_execution
    executenb(
  File "/home/andrew/anaconda3/envs/jupbooks/lib/python3.8/site-packages/nbclient/client.py", line 1112, in execute
    return NotebookClient(nb=nb, resources=resources, km=km, **kwargs).execute()
  File "/home/andrew/anaconda3/envs/jupbooks/lib/python3.8/site-packages/nbclient/util.py", line 74, in wrapped
    return just_run(coro(*args, **kwargs))
  File "/home/andrew/anaconda3/envs/jupbooks/lib/python3.8/site-packages/nbclient/util.py", line 53, in just_run
    return loop.run_until_complete(coro)
  File "/home/andrew/anaconda3/envs/jupbooks/lib/python3.8/asyncio/base_events.py", line 616, in run_until_complete
    return future.result()
  File "/home/andrew/anaconda3/envs/jupbooks/lib/python3.8/site-packages/nbclient/client.py", line 553, in async_execute
    await self.async_execute_cell(
  File "/home/andrew/anaconda3/envs/jupbooks/lib/python3.8/site-packages/nbclient/client.py", line 857, in async_execute_cell
    self._check_raise_for_error(cell, exec_reply)
  File "/home/andrew/anaconda3/envs/jupbooks/lib/python3.8/site-packages/nbclient/client.py", line 760, in _check_raise_for_error
    raise CellExecutionError.from_cell_and_msg(cell, exec_reply_content)
nbclient.exceptions.CellExecutionError: An error occurred while executing the following cell:
------------------
my_path = input("Path to search: ")
to_find = input("Name of file to find: ")

print(find_all(to_find, my_path))
------------------

[0;31m---------------------------------------------------------------------------[0m
[0;31mStdinNotImplementedError[0m                  Traceback (most recent call last)
[0;32m<ipython-input-9-9c86906a22c9>[0m in [0;36m<module>[0;34m[0m
[0;32m----> 1[0;31m [0mmy_path[0m [0;34m=[0m [0minput[0m[0;34m([0m[0;34m"Path to search: "[0m[0;34m)[0m[0;34m[0m[0;34m[0m[0m
[0m[1;32m      2[0m [0mto_find[0m [0;34m=[0m [0minput[0m[0;34m([0m[0;34m"Name of file to find: "[0m[0;34m)[0m[0;34m[0m[0;34m[0m[0m
[1;32m      3[0m [0;34m[0m[0m
[1;32m      4[0m [0mprint[0m[0;34m([0m[0mfind_all[0m[0;34m([0m[0mto_find[0m[0;34m,[0m [0mmy_path[0m[0;34m)[0m[0;34m)[0m[0;34m[0m[0;34m[0m[0m

[0;32m~/anaconda3/envs/data_science/lib/python3.9/site-packages/ipykernel/kernelbase.py[0m in [0;36mraw_input[0;34m(self, prompt)[0m
[1;32m    855[0m         """
[1;32m    856[0m         [0;32mif[0m [0;32mnot[0m [0mself[0m[0;34m.[0m[0m_allow_stdin[0m[0;34m:[0m[0;34m[0m[0;34m[0m[0m
[0;32m--> 857[0;31m             raise StdinNotImplementedError(
[0m[1;32m    858[0m                 [0;34m"raw_input was called, but this frontend does not support input requests."[0m[0;34m[0m[0;34m[0m[0m
[1;32m    859[0m             )

[0;31mStdinNotImplementedError[0m: raw_input was called, but this frontend does not support input requests.
StdinNotImplementedError: raw_input was called, but this frontend does not support input requests.

